Workbook

Sheet Resumen deber ser
A1: Resumen del deber ser
A2: Se calcula a partir de la hoja Deber ser.
A4: Grupo | B4: Menús | C4: Opciones | D4: Ya funcionan (Existe o Unir) | E4: Por trabajar | F4: Fase 1 | G4: Fase 2 | H4: Fase 3 | I4: Avance promedio
A5: Mi día | B5: 1 | C5: =COUNTIF('Deber ser'!$B$5:$B$104,A5) -> 5 | D5: =COUNTIFS('Deber ser'!$B$5:$B$104,A5,'Deber ser'!$G$5:$G$104,"Existe")+COUNTIFS('Deber ser'!$B$5:$B$104,A5,'Deber ser'!$G$5:$G$104,"Unir") -> 4 | E5: =C5-D5 -> 1 | F5: =COUNTIFS('Deber ser'!$B$5:$B$104,$A5,'Deber ser'!$I$5:$I$104,"Fase 1") -> 3 | G5: =COUNTIFS('Deber ser'!$B$5:$B$104,$A5,'Deber ser'!$I$5:$I$104,"Fase 2") -> 2 | H5: =COUNTIFS('Deber ser'!$B$5:$B$104,$A5,'Deber ser'!$I$5:$I$104,"Fase 3") -> 0 | I5: =IFERROR(AVERAGEIF('Deber ser'!$B$5:$B$104,A5,'Deber ser'!$N$5:$N$104),0) -> 0
A6: Dirección | B6: 3 | C6: =COUNTIF('Deber ser'!$B$5:$B$104,A6) -> 11 | D6: =COUNTIFS('Deber ser'!$B$5:$B$104,A6,'Deber ser'!$G$5:$G$104,"Existe")+COUNTIFS('Deber ser'!$B$5:$B$104,A6,'Deber ser'!$G$5:$G$104,"Unir") -> 2 | E6: =C6-D6 -> 9 | F6: =COUNTIFS('Deber ser'!$B$5:$B$104,$A6,'Deber ser'!$I$5:$I$104,"Fase 1") -> 4 | G6: =COUNTIFS('Deber ser'!$B$5:$B$104,$A6,'Deber ser'!$I$5:$I$104,"Fase 2") -> 7 | H6: =COUNTIFS('Deber ser'!$B$5:$B$104,$A6,'Deber ser'!$I$5:$I$104,"Fase 3") -> 0 | I6: =IFERROR(AVERAGEIF('Deber ser'!$B$5:$B$104,A6,'Deber ser'!$N$5:$N$104),0) -> 0
A7: Comercial | B7: 4 | C7: =COUNTIF('Deber ser'!$B$5:$B$104,A7) -> 19 | D7: =COUNTIFS('Deber ser'!$B$5:$B$104,A7,'Deber ser'!$G$5:$G$104,"Existe")+COUNTIFS('Deber ser'!$B$5:$B$104,A7,'Deber ser'!$G$5:$G$104,"Unir") -> 6 | E7: =C7-D7 -> 13 | F7: =COUNTIFS('Deber ser'!$B$5:$B$104,$A7,'Deber ser'!$I$5:$I$104,"Fase 1") -> 12 | G7: =COUNTIFS('Deber ser'!$B$5:$B$104,$A7,'Deber ser'!$I$5:$I$104,"Fase 2") -> 6 | H7: =COUNTIFS('Deber ser'!$B$5:$B$104,$A7,'Deber ser'!$I$5:$I$104,"Fase 3") -> 1 | I7: =IFERROR(AVERAGEIF('Deber ser'!$B$5:$B$104,A7,'Deber ser'!$N$5:$N$104),0) -> 0
A8: Finanzas | B8: 4 | C8: =COUNTIF('Deber ser'!$B$5:$B$104,A8) -> 24 | D8: =COUNTIFS('Deber ser'!$B$5:$B$104,A8,'Deber ser'!$G$5:$G$104,"Existe")+COUNTIFS('Deber ser'!$B$5:$B$104,A8,'Deber ser'!$G$5:$G$104,"Unir") -> 12 | E8: =C8-D8 -> 12 | F8: =COUNTIFS('Deber ser'!$B$5:$B$104,$A8,'Deber ser'!$I$5:$I$104,"Fase 1") -> 18 | G8: =COUNTIFS('Deber ser'!$B$5:$B$104,$A8,'Deber ser'!$I$5:$I$104,"Fase 2") -> 6 | H8: =COUNTIFS('Deber ser'!$B$5:$B$104,$A8,'Deber ser'!$I$5:$I$104,"Fase 3") -> 0 | I8: =IFERROR(AVERAGEIF('Deber ser'!$B$5:$B$104,A8,'Deber ser'!$N$5:$N$104),0) -> 0
A9: Operación | B9: 4 | C9: =COUNTIF('Deber ser'!$B$5:$B$104,A9) -> 15 | D9: =COUNTIFS('Deber ser'!$B$5:$B$104,A9,'Deber ser'!$G$5:$G$104,"Existe")+COUNTIFS('Deber ser'!$B$5:$B$104,A9,'Deber ser'!$G$5:$G$104,"Unir") -> 3 | E9: =C9-D9 -> 12 | F9: =COUNTIFS('Deber ser'!$B$5:$B$104,$A9,'Deber ser'!$I$5:$I$104,"Fase 1") -> 6 | G9: =COUNTIFS('Deber ser'!$B$5:$B$104,$A9,'Deber ser'!$I$5:$I$104,"Fase 2") -> 0 | H9: =COUNTIFS('Deber ser'!$B$5:$B$104,$A9,'Deber ser'!$I$5:$I$104,"Fase 3") -> 9 | I9: =IFERROR(AVERAGEIF('Deber ser'!$B$5:$B$104,A9,'Deber ser'!$N$5:$N$104),0) -> 0
A10: Nómina y mano de obra | B10: 2 | C10: =COUNTIF('Deber ser'!$B$5:$B$104,A10) -> 8 | D10: =COUNTIFS('Deber ser'!$B$5:$B$104,A10,'Deber ser'!$G$5:$G$104,"Existe")+COUNTIFS('Deber ser'!$B$5:$B$104,A10,'Deber ser'!$G$5:$G$104,"Unir") -> 1 | E10: =C10-D10 -> 7 | F10: =COUNTIFS('Deber ser'!$B$5:$B$104,$A10,'Deber ser'!$I$5:$I$104,"Fase 1") -> 7 | G10: =COUNTIFS('Deber ser'!$B$5:$B$104,$A10,'Deber ser'!$I$5:$I$104,"Fase 2") -> 1 | H10: =COUNTIFS('Deber ser'!$B$5:$B$104,$A10,'Deber ser'!$I$5:$I$104,"Fase 3") -> 0 | I10: =IFERROR(AVERAGEIF('Deber ser'!$B$5:$B$104,A10,'Deber ser'!$N$5:$N$104),0) -> 0
A11: Administración | B11: 4 | C11: =COUNTIF('Deber ser'!$B$5:$B$104,A11) -> 18 | D11: =COUNTIFS('Deber ser'!$B$5:$B$104,A11,'Deber ser'!$G$5:$G$104,"Existe")+COUNTIFS('Deber ser'!$B$5:$B$104,A11,'Deber ser'!$G$5:$G$104,"Unir") -> 6 | E11: =C11-D11 -> 12 | F11: =COUNTIFS('Deber ser'!$B$5:$B$104,$A11,'Deber ser'!$I$5:$I$104,"Fase 1") -> 14 | G11: =COUNTIFS('Deber ser'!$B$5:$B$104,$A11,'Deber ser'!$I$5:$I$104,"Fase 2") -> 4 | H11: =COUNTIFS('Deber ser'!$B$5:$B$104,$A11,'Deber ser'!$I$5:$I$104,"Fase 3") -> 0 | I11: =IFERROR(AVERAGEIF('Deber ser'!$B$5:$B$104,A11,'Deber ser'!$N$5:$N$104),0) -> 0
A12: Total | B12: =SUM(B5:B11) -> 22 | C12: =SUM(C5:C11) -> 100 | D12: =SUM(D5:D11) -> 34 | E12: =SUM(E5:E11) -> 66 | F12: =SUM(F5:F11) -> 64 | G12: =SUM(G5:G11) -> 26 | H12: =SUM(H5:H11) -> 10 | I12: =IFERROR(AVERAGE('Deber ser'!$N$5:$N$104),0) -> 0
A14: Fases
A15: Fase 1 | B15: Lo indispensable para operar el grupo: cobrar, pagar, comprar, almacén, presupuestos, nómina y mano de obra.
A16: Fase 2 | B16: Control y consolidación: estado de resultados, traspasos, inventario físico, comisiones, legal, bitácora.
A17: Fase 3 | B17: Operación de cada negocio: producción, fletes, rentas y calificación de proyectos.
A19: Barra superior
A20: Mi día | B20: Dirección | C20: Comercial | D20: Finanzas | E20: Operación | F20: Nómina y mano de obra | G20: Administración
A21: Mi día | B21: Tablero · Análisis · Gobierno | C21: Ventas · Cobranza · Compras · Almacén | D21: Tesorería · Cuentas por pagar · Presupuestos · Contabilidad | E21: Obras · Producción · Fletes · Mantenimiento BBVA | F21: Nómina · Mano de obra | G21: Recursos humanos · Legal y cumplimiento · Catálogos · Configuración

Sheet Deber ser
A1: Deber ser · Acumulado para el grupo
A2: 7 grupos, máximo 7 opciones por menú. Une la hoja Match con las pantallas fuera de estructura. Columnas amarillas para llenar.
A4: # | B4: Grupo | C4: Menú | D4: Opción | E4: Qué hace | F4: Viene de | G4: Estatus | H4: Ruta en Acumulado | I4: Fase | J4: Quién la usa | K4: Prioridad | L4: Responsable | M4: Fecha compromiso | N4: Avance
A5: 1 | B5: Mi día | C5: Mi día | D5: Inicio | E5: Mis pendientes y alertas del día según mi puesto | F5: Match 1.a, 1.d | G5: Ajustar | H5: / | I5: Fase 1 | J5: Todos | N5: 0
A6: 2 | B6: Mi día | C6: Mi día | D6: Mis tareas | E6: Una sola lista de actividades con filtro por área | F6: Fuera: Tareas y 9 Tareas de área | G6: Unir | H6: /tareas | I6: Fase 1 | J6: Todos | N6: 0
A7: 3 | B7: Mi día | C7: Mi día | D7: Checador | E7: Entrada, comida y salida con foto y ubicación; alimenta Asistencia | F7: Fuera: Checador | G7: Existe | H7: /checador | I7: Fase 1 | J7: Todos | N7: 0
A8: 4 | B8: Mi día | C8: Mi día | D8: Comedor | E8: Pedido de comida con descuento vía nómina | F8: Fuera: Comedor | G8: Existe | H8: /comedor | I8: Fase 2 | J8: Todos | N8: 0
A9: 5 | B9: Mi día | C9: Mi día | D9: Mi perfil | E9: Personaje, QR, contrato y documentos por firmar en una sola pantalla | F9: Fuera: Mi personaje, Mis documentos | G9: Unir | H9: /personaje; /mis-documentos | I9: Fase 2 | J9: Todos | N9: 0
A10: 6 | B10: Dirección | C10: Tablero | D10: Resumen del grupo | E10: KPIs con semáforo contra presupuesto y año anterior; clic para bajar de grupo a empresa, centro y documento | F10: Match 1.b | G10: Ajustar | H10: /dashboard | I10: Fase 1 | J10: Dirección, Finanzas | N10: 0
A11: 7 | B11: Dirección | C11: Tablero | D11: Bandeja de aprobaciones | E11: Todo lo que espera al CEO en un solo lugar: OC, pagos, nóminas, estimaciones y préstamos entre empresas | F11: Fuera: Órdenes por autorizar; Nuevo: criterio SAP | G11: Ajustar | H11: /finanzas/por-autorizar | I11: Fase 1 | J11: Dirección | N11: 0
A12: 8 | B12: Dirección | C12: Tablero | D12: Alertas de dirección | E12: Solo excepciones: flujo en rojo, obras desviadas, cobros vencidos, opiniones fiscales negativas | F12: Nuevo: criterio SAP | G12: Crear | I12: Fase 1 | J12: Dirección | N12: 0
A13: 9 | B13: Dirección | C13: Tablero | D13: Seguimiento de obras | E13: Avance físico contra avance financiero por obra | F13: Match 1.c, 6.e | G13: Existe | H13: /finanzas/obras | I13: Fase 1 | J13: Dirección, Obra | N13: 0
A14: 10 | B14: Dirección | C14: Análisis | D14: Estado de resultados | E14: Real contra presupuesto y año anterior, por empresa y consolidado, con drill-down a la póliza o documento | F14: Match 15.d | G14: Crear | I14: Fase 2 | J14: Dirección, Finanzas | N14: 0
A15: 11 | B15: Dirección | C15: Análisis | D15: Rentabilidad por centro de beneficio | E15: Utilidad por empresa, obra y línea de negocio (materiales, fábricas, fletes, TI) | F15: Nuevo: criterio SAP | G15: Crear | I15: Fase 2 | J15: Dirección, Finanzas | N15: 0
A16: 12 | B16: Dirección | C16: Análisis | D16: Comparativo entre empresas | E16: Las 8 empresas lado a lado: ventas, margen, gasto, flujo y cartera | F16: Nuevo: criterio SAP | G16: Crear | I16: Fase 2 | J16: Dirección | N16: 0
A17: 13 | B17: Dirección | C17: Análisis | D17: Reportes | E17: Ingresos, ingresos y egresos por proyecto, compras vs ventas, historial y reportes especiales en pestañas | F17: Match 15.a, 15.b, 15.c, 15.e; Fuera: Reportes especiales | G17: Migrar del backoffice | H17: /reportes | I17: Fase 2 | J17: Dirección, Finanzas | N17: 0
A18: 14 | B18: Dirección | C18: Gobierno | D18: Metas y objetivos | E18: Metas anuales por empresa y área, con avance automático desde los datos del sistema | F18: Nuevo: criterio SAP | G18: Crear | I18: Fase 2 | J18: Dirección | N18: 0
A19: 15 | B19: Dirección | C19: Gobierno | D19: Acuerdos de junta | E19: Acuerdos de dirección con responsable, fecha y seguimiento ligado a Mis tareas | F19: Nuevo: criterio SAP | G19: Crear | I19: Fase 2 | J19: Dirección | N19: 0
A20: 16 | B20: Dirección | C20: Gobierno | D20: Vista de socio | E20: Lo que consulta cada socio | F20: Fuera: Socio | G20: Existe | H20: /socio | I20: Fase 2 | J20: Socios | N20: 0
A21: 17 | B21: Comercial | C21: Ventas | D21: Cotizaciones | E21: Cotizar a clientes de cualquier empresa | F21: Match 2.a | G21: Existe | H21: /cotizador | I21: Fase 1 | J21: Ventas | N21: 0
A22: 18 | B22: Comercial | C22: Ventas | D22: CRM | E22: Contactos de WhatsApp y redes, seguimiento y canales de venta | F22: Fuera: CRM de ventas; Match 16.g | G22: Ajustar | H22: /ventas/crm | I22: Fase 2 | J22: Ventas | N22: 0
A23: 19 | B23: Comercial | C23: Ventas | D23: Órdenes de venta | E23: OV a clientes externos y a empresas del grupo (tipo: entre empresas) | F23: Match 2.b, 2.f | G23: Ajustar | H23: /ordenes?tipo=OV | I23: Fase 1 | J23: Ventas | N23: 0
A24: 20 | B24: Comercial | C24: Ventas | D24: Facturación | E24: Facturas y notas de crédito ligadas a la OV | F24: Match 2.c, 2.d | G24: Migrar del backoffice | I24: Fase 1 | J24: Ventas, Contabilidad | N24: 0
A25: 21 | B25: Comercial | C25: Ventas | D25: Rentas y leasing | E25: Contratos de renta y leasing con su calendario de cobro | F25: Match 2.e | G25: Crear | I25: Fase 3 | J25: Ventas, Finanzas | N25: 0
A26: 22 | B26: Comercial | C26: Ventas | D26: Acumulado | E26: Definir qué debe mostrar antes de programarlo | F26: Match 2.g | G26: Por definir | I26: Fase 2 | J26: Por definir | N26: 0
A27: 23 | B27: Comercial | C27: Cobranza | D27: Cuentas por cobrar | E27: Saldo por cliente con antigüedad (al corriente, 30, 60, 90+ días) | F27: Match 3.a, 3.b | G27: Crear | I27: Fase 1 | J27: Finanzas, Ventas | N27: 0
A28: 24 | B28: Comercial | C28: Cobranza | D28: Registro de cobros | E28: Aplicar depósitos del banco a facturas | F28: Match 3.c | G28: Crear | I28: Fase 1 | J28: Finanzas | N28: 0
A29: 25 | B29: Comercial | C29: Cobranza | D29: Crédito a clientes | E29: Línea, días de crédito y contrato por cliente | F29: Match 3.d | G29: Ajustar | H29: /legal?tab=credito | I29: Fase 2 | J29: Finanzas, Legal | N29: 0
A30: 26 | B30: Comercial | C30: Compras | D30: Requisiciones | E30: Solicitudes de material de obra o almacén | F30: Match 4.a | G30: Existe | H30: /requisiciones | I30: Fase 1 | J30: Obra, Almacén, Compras | N30: 0
A31: 27 | B31: Comercial | C31: Compras | D31: Órdenes de compra y servicio | E31: OC/OS con estado, editar y cancelar; tipo entre empresas para AEP | F31: Match 4.b, 4.c, 4.e | G31: Validar | H31: /ordenes | I31: Fase 1 | J31: Compras | N31: 0
A32: 28 | B32: Comercial | C32: Compras | D32: Confirmar factura | E32: Ligar el CFDI del proveedor a su OC | F32: Match 4.d | G32: Validar | H32: /carga | I32: Fase 1 | J32: Compras, Contabilidad | N32: 0
A33: 29 | B33: Comercial | C33: Almacén | D33: Por recibir | E33: OC pagadas pendientes de llegar, con avance por partida | F33: Match 8.b; Fuera: Por recibir, Match con OC/OV | G33: Unir | H33: /inventario/por-recibir; /inventario/match | I33: Fase 1 | J33: Almacén | N33: 0
A34: 30 | B34: Comercial | C34: Almacén | D34: Entradas y salidas | E34: Registrar movimientos contra la OC o la OV | F34: Match 8.b, 8.c | G34: Existe | H34: /inventario | I34: Fase 1 | J34: Almacén | N34: 0
A35: 31 | B35: Comercial | C35: Almacén | D35: Remisiones | E35: Entregas de almacén a obra o cliente con QR | F35: Match 8.c | G35: Existe | H35: /inventario/remisiones | I35: Fase 1 | J35: Almacén, Logística | N35: 0
A36: 32 | B36: Comercial | C36: Almacén | D36: Existencias | E36: Lo que hay por almacén, valor por empresa y kardex por artículo | F36: Match 8.a, 8.f; Fuera: Resumen de inventario | G36: Ajustar | H36: /inventario/existencias; /inventario/resumen | I36: Fase 1 | J36: Almacén, Compras | N36: 0
A37: 33 | B37: Comercial | C37: Almacén | D37: Traspasos entre empresas | E37: Mover material de AEP a otra empresa con su venta interna | F37: Match 8.d | G37: Crear | I37: Fase 2 | J37: Almacén | N37: 0
A38: 34 | B38: Comercial | C38: Almacén | D38: Inventario físico | E38: Conteo y ajuste contra sistema | F38: Match 8.e | G38: Crear | I38: Fase 2 | J38: Almacén | N38: 0
A39: 35 | B39: Comercial | C39: Almacén | D39: Herramienta y equipo | E39: Piezas con folio, préstamos a obra y resguardos | F39: Fuera: Herramienta y equipo | G39: Existe | H39: /almacen/herramienta | I39: Fase 2 | J39: Almacén, Obra | N39: 0
A40: 36 | B40: Finanzas | C40: Tesorería | D40: Pagos de hoy | E40: Semáforo por empresa y pagos del día con datos bancarios | F40: Match 5.c | G40: Existe | H40: /finanzas/tesoreria | I40: Fase 1 | J40: Tesorería | N40: 0
A41: 37 | B41: Finanzas | C41: Tesorería | D41: Programación de pagos | E41: Calendario de pagos por empresa | F41: Match 5.b | G41: Existe | H41: /finanzas/pagos | I41: Fase 1 | J41: Tesorería | N41: 0
...

Sheet Reglas de diseño
A1: Reglas para que Acumulado sea fácil, bonito y funcione para el grupo
A3: Tema | B3: Regla | C3: Por qué
A4: Menú | B4: Máximo 7 grupos en la barra superior y 7 opciones por menú | C4: Todo cabe a la vista y nadie se pierde
A5: Menú | B5: Agrupar por proceso (vender, cobrar, comprar, pagar, operar), no por departamento | C5: Una tarea no se reparte entre menús
A6: Menú | B6: Cada quien ve solo los menús de su rol | C6: Menos ruido; el almacenista no ve tesorería
A7: Menú | B7: Nombres cortos y en español claro; sin siglas internas ni números | C7: 'Autorizar órdenes' se entiende; 'Tmp Cpis' no
A8: Empresas | B8: Un selector de empresa arriba, con 'Todas' para ver el consolidado | C8: Mismas pantallas para las 7 empresas
A9: Empresas | B9: Las ventas, compras y traspasos entre empresas se marcan como tales | C9: El consolidado no duplica ingresos ni gastos
A10: Pantallas | B10: Una pantalla por tarea; variantes como pestañas, no como opciones de menú | C10: Saldos por empresa y por cuenta son una sola pantalla
A11: Pantallas | B11: Todas las listas con los mismos filtros: empresa, fechas, estatus y buscador | C11: Se aprende una vez
A12: Pantallas | B12: Estatus con los mismos colores en todo el sistema: verde listo, ámbar pendiente, rojo vencido | C12: Se lee de un vistazo
A13: Pantallas | B13: Botón Exportar a Excel e Imprimir en cada lista | C13: Sustituye las opciones sueltas de exportar
A14: Pantallas | B14: Inicio muestra solo alertas que requieren acción, con enlace directo | C14: El usuario no busca, el sistema le avisa
... A19: Diseño | B19: Gamificación (personaje, XP) solo en Mi día | C19: Motiva sin distraer en pantallas de trabajo

Sheet Criterio SAP
A1: Criterio tipo SAP aplicado a Acumulado
A2: No se trata de instalar SAP, sino de tomar sus principios para que dirección decida con datos confiables.
A4: Principio | B4: Qué significa | C4: Cómo queda en Acumulado
A5: Sociedades | B5: Cada empresa es una sociedad; todo documento pertenece a una sola. | C5: Selector de empresa arriba; consolidado con 'Todas'.
A6: Centros de costo y de beneficio | B6: Cada peso de gasto o ingreso tiene un centro y un responsable. | C6: Catálogos › Centros de costo y de beneficio; campo obligatorio en OC, nómina y facturas.
A7: Datos maestros únicos | B7: Un solo catálogo de clientes, proveedores, productos y empleados para el grupo. | C7: Catálogos compartidos, filtrados por empresa.
A8: Documento integrado | B8: Un documento fluye por todo el proceso sin recapturarse. | C8: Requisición › OC › recepción › factura › pago › presupuesto contra real.
A9: Flujos de aprobación | B9: Las aprobaciones siguen reglas por monto y empresa, no mensajes. | C9: Matriz de autorizaciones y Bandeja de aprobaciones.
A10: Drill-down | B10: Desde cualquier número se baja al documento que lo origina. | C10: Tablero › empresa › centro › documento.
A11: Cierre de periodo | B11: Al cerrar un mes, nadie modifica esa información. | C11: Contabilidad › Cierre del mes.
A12: Gestión por excepción | B12: Dirección ve solo lo que se sale de lo esperado. | C12: Tablero › Alertas de dirección con semáforos.
A13: Plan contra real | B13: Todo se compara contra presupuesto y año anterior. | C13: Presupuestos alimenta Tablero, Análisis y Metas.
A15: Equivalencia con módulos SAP
A16: SAP | B16: En Acumulado
A17: FI · Finanzas | B17: Tesorería, Cuentas por pagar, Cobranza, Contabilidad
A18: CO · Controlling | B18: Centros de costo y de beneficio, Presupuestos, Rentabilidad
A19: SD · Ventas | B19: Ventas, Cobranza
A20: MM · Materiales | B20: Compras, Almacén
A21: PP · Producción | B21: Producción
A22: PS · Proyectos | B22: Obras, Contratos y estimaciones, Mano de obra
A23: HCM · Capital humano | B23: Recursos humanos, Organigrama, Vacantes
A24: Fiori Launchpad | B24: Mi día y Tablero: cada quien ve solo sus tarjetas

Sheet Especificaciones
A1: Especificación de las opciones nuevas
A2: Punto de partida para el programador; ajústalo con quien usará cada pantalla.
A4: Opción | B4: Dónde va | C4: Fase | D4: Empresas | E4: Para qué sirve | F4: Pestañas | G4: Datos que captura | H4: Reglas | I4: Se conecta con | J4: Quién la usa
A5: Contratos y estimaciones | B5: Operación › Obras | C5: Fase 1 | D5: CSC, Ergodinova, Mario Contreras Farfán | E5: Controlar cada obra desde el contrato hasta el finiquito, y saber cuánto se ha estimado, cobrado y retenido. | F5: Contratos · Estimaciones · Anticipos · Retenciones y fianzas · Finiquito | G5: Cliente, obra, monto contratado, IVA, % de anticipo, amortización del anticipo por estimación, retenciones (fondo de garantía, 5 al millar en obra pública), fianzas (anticipo, cumplimiento, vicios ocultos), convenios modificatorios, periodo y volumen estimado por concepto. | H5: Una estimación no puede exceder lo contratado más convenios. El anticipo se amortiza en cada estimación. Al autorizar una estimación se genera la factura y la cuenta por cobrar. | I5: Proyectos, Precios unitarios, Facturación, Cuentas por cobrar, Seguros y fianzas, Presupuesto por obra | J5: Residente (captura) · Finanzas (autoriza y factura) · Legal (contrato y fianzas)
A6: Matriz de autorizaciones | B6: Administración › Configuración | C6: Fase 1 | D6: Todas (una sola matriz para el grupo) | E6: Que cada OC, pago, nómina o estimación la autorice la persona correcta según monto y empresa, sin depender de mensajes. | F6: Reglas · Autorizadores · Historial | G6: Tipo de documento (OC, OS, pago, nómina, estimación, préstamo entre empresas), empresa, rango de monto, autorizador principal y suplente, número de firmas. | H6: Si no hay regla, el documento no avanza. Un usuario no autoriza lo que él mismo capturó. Cada autorización queda en la bitácora. | I6: Autorizar órdenes, Programación de pagos, Nómina, Contratos y estimaciones, Bitácora de cambios | J6: Dirección (define montos) · TI (configura)
A7: Cumplimiento fiscal | B7: Finanzas › Contabilidad | C7: Fase 1 | D7: Las 8 razones sociales | E7: No vencer obligaciones ante el SAT, IMSS e Infonavit en ninguna empresa. | F7: Calendario · Opiniones de cumplimiento · DIOT · Expediente fiscal | G7: Obligación, empresa, periodicidad, fecha límite, responsable, estatus, acuse en PDF, fecha de la última opinión de cumplimiento (SAT, IMSS, Infonavit). | H7: Avisa 5 días antes del vencimiento. Una opinión negativa aparece como alerta en Inicio de Dirección y Contabilidad. | I7: Perfil fiscal, Carga de archivos, Inicio (alertas) | J7: Contabilidad (captura) · Dirección (consulta)
A8: Eliminaciones entre empresas | B8: Finanzas › Contabilidad | C8: Fase 2 | D8: Todas | E8: Que el consolidado no sume dos veces lo que una empresa le vende, compra o presta a otra. | F8: Operaciones por cuadrar · Diferencias · Resumen para consolidado | G8: Se alimenta solo de OV, OC, traspasos y préstamos marcados como entre empresas. Empresa que vende, empresa que compra, monto, mes. | H8: Lo vendido por una debe igualar lo comprado por la otra; si no, aparece como diferencia por revisar. El estado de resultados consolidado resta lo cuadrado. | I8: Órdenes de venta, Órdenes de compra, Traspasos entre empresas, Préstamos entre empresas, Estado de resultados | J8: Contabilidad (cuadra) · Dirección (consulta)
A9: Activos fijos | B9: Finanzas › Contabilidad | C9: Fase 2 | D9: Todas; más peso en Loma Racing, Clavicon, Balken y constructoras | E9: Saber qué activos tiene cada empresa, dónde están, quién los tiene y cuánto valen. | F9: Inventario de activos · Resguardos · Depreciación · Bajas | G9: Activo, empresa dueña, categoría (maquinaria, vehículo, equipo de obra, cómputo), factura, costo, fecha de compra, ubicación u obra, responsable, tasa de depreciación, número de serie o placa. | H9: Depreciación mensual automática. Un activo prestado a otra empresa queda registrado como préstamo entre empresas. Las unidades de Loma Racing se ligan con Fletes. | I9: Herramienta y equipo, Unidades y mantenimiento, Seguros y fianzas, Contabilidad | J9: Contabilidad (alta y depreciación) · Almacén o Jefe de flota (resguardo)
A10: Seguros y fianzas | B10: Administración › Legal y cumplimiento | C10: Fase 2 | D10: Todas | E10: Que ninguna unidad, obra o equipo quede sin seguro ni fianza vigente. | F10: Pólizas · Fianzas · Vencimientos · Siniestros | G10: Aseguradora o afianzadora, póliza, empresa, qué cubre (unidad, obra, equipo, responsabilidad civil), vigencia, prima, beneficiario, documento PDF. | H10: Avisa 30 días antes del vencimiento. Las fianzas de obra se crean desde el contrato. Un siniestro abierto queda como alerta hasta cerrarse. | I10: Contratos y estimaciones, Activos fijos, Unidades y mantenimiento, Cuentas por pagar | J10: Legal (captura) · Finanzas (paga primas)
A11: Resumen del grupo (tablero del CEO) | B11: Dirección › Tablero | C11: Fase 1 | D11: Todas | E11: Que el CEO vea en una pantalla cómo va el grupo y pueda bajar hasta el documento que explica cada número. | F11: Grupo · Por empresa · Por centro de beneficio | G11: No se captura: se alimenta de Tesorería, Cobranza, Cuentas por pagar, Presupuestos y Obras. KPIs: saldo en bancos, flujo a 13 semanas, ventas, margen, cartera vencida, pagos por vencer, avance de obras, nómina. | H11: Cada KPI con semáforo contra presupuesto y año anterior. Clic en un número: grupo › empresa › centro › documento. Mismo número en todas las pantallas (una sola fuente). | I11: Todos los módulos; Centros de costo y de beneficio; Presupuestos | J11: Dirección general · Socios (consulta)
A12: Bandeja de aprobaciones | B12: Dirección › Tablero | C12: Fase 1 | D12: Todas | E12: Que todo lo que requiere visto bueno de dirección esté en un solo lugar, con el contexto para decidir. | F12: Pendientes · Aprobadas · Rechazadas | G12: Documento, empresa, monto, quién lo pide, presupuesto disponible, historial con ese proveedor o empleado. | H12: Llega según la Matriz de autorizaciones. Aprobar o rechazar con comentario, también desde el celular. Lo rechazado regresa a quien lo capturó. | I12: Matriz de autorizaciones, Órdenes de compra, Programación de pagos, Nómina, Contratos y estimaciones | J12: Dirección general y autorizadores
A13: Rentabilidad por centro de beneficio | B13: Dirección › Análisis | C13: Fase 2 | D13: Todas | E13: Saber qué empresa, obra o línea de negocio deja dinero y cuál no. | F13: Por empresa · Por obra · Por línea de negocio | G13: No se captura: ingresos y gastos asignados a cada centro de beneficio. | H13: Margen real contra presupuesto. Las operaciones entre empresas se muestran aparte para no inflar la utilidad. | I13: Centros de costo y de beneficio, Estado de resultados, Eliminaciones entre empresas | J13: Dirección · Finanzas
A14: Centros de costo y de beneficio | B14: Administración › Catálogos | C14: Fase 1 | D14: Todas | E14: La base del criterio SAP: que cada peso de gasto o ingreso tenga dueño. | F14: Estructura · Responsables | G14: Empresa (sociedad), centro de beneficio (obra, línea de negocio), centro de costo (área: administración, almacén, flota, producción), responsable. | H14: Toda OC, OS, nómina, factura y gasto lleva centro obligatorio. Un centro solo pertenece a una empresa. | I14: Órdenes de compra, Nómina, Facturación, Comprobación de gastos, Presupuestos | J14: Finanzas (define) · TI (configura)
A15: Metas y objetivos | B15: Dirección › Gobierno | C15: Fase 2 | D15: Todas | E15: Que las metas anuales del grupo se midan solas con los datos del sistema. | F15: Metas del año · Avance · Histórico | G15: Meta, empresa o área, indicador (ligado a un KPI del sistema), valor objetivo, responsable, periodo. | H15: El avance se calcula solo; nadie lo captura a mano. | I15: Resumen del grupo, Presupuestos, Organigrama | J15: Dirección · jefes de área (consulta)
... A20: Vacantes | B20: Administración › Recursos humanos | C20: Fase 1 | D20: Todas | E20: Saber qué puestos están abiertos, en qué etapa va cada uno y cuánto tiempo llevan. | F20: Vacantes abiertas · Candidatos · Cerradas | G20: Puesto (ligado a su descripción), empresa, área, quién lo solicita, motivo (nueva o reemplazo), sueldo, fecha de apertura, candidatos, etapa (solicitud, búsqueda, entrevistas, oferta, contratado). | H20: Toda vacante nueva pasa por la Matriz de autorizaciones. Al contratar, el candidato se convierte en expediente sin volver a capturar. Días abierta con semáforo. | I20: Descripciones de puesto, Organigrama, Expediente del empleado, Bandeja de aprobaciones | J20: RH · Dirección · jefes que solicitan

Sheet Empresas x módulos
A1: Qué módulos ocupa cada empresa
A2: Valores: Usa · Vía AEP (lo hace AEP por ella) · Compartido (uno para todo el grupo) · Opcional · Por confirmar · No aplica. Se pueden cambiar con la lista.
A4: Grupo | B4: Menú | C4: CSC Loma | D4: Ergodinova | E4: AEP | F4: Clavicon | G4: Loma Racing | H4: Balken | I4: Qx Soluciones | J4: Mario Contreras Farfán | K4: Nota
B5: Giro | C5: Construcción pública y privada | D5: Construcción privada, industria automotriz | E5: Casa de materiales; compra para todo el grupo | F5: Fábrica trefiladora | G5: Fletera | H5: Fábrica de viguetas, bloques y bovedillas | I5: Tecnologías de información | J5: Construcción
A6: Mi día | B6: Mi día | C6: Usa | D6: Usa | E6: Usa | F6: Usa | G6: Usa | H6: Usa | I6: Usa | J6: Usa | K6: Todo empleado: checador, tareas, comedor y perfil.
A7: Dirección | B7: Tablero | C7: Usa | D7: Usa | E7: Usa | F7: Usa | G7: Usa | H7: Usa | I7: Usa | J7: Usa | K7: Cada empresa aparece en el tablero y en el consolidado.
A8: Dirección | B8: Análisis | C8: Usa | D8: Usa | E8: Usa | F8: Usa | G8: Usa | H8: Usa | I8: Usa | J8: Usa | K8: Rentabilidad por empresa y centro de beneficio.
A9: Dirección | B9: Gobierno | C9: Usa | D9: Usa | E9: Usa | F9: Usa | G9: Usa | H9: Usa | I9: Usa | J9: Usa | K9: Metas por empresa; acuerdos de junta del grupo.
A10: Comercial | B10: Ventas | C10: Usa | D10: Usa | E10: Usa | F10: Usa | G10: Usa | H10: Usa | I10: Usa | J10: Usa | K10: CSC, Ergo y Mario Contreras Farfán facturan obra; AEP, Clavicon y Balken venden producto; Loma Racing factura fletes; Qx factura sistemas.
A11: Comercial | B11: Cobranza | C11: Usa | D11: Usa | E11: Usa | F11: Usa | G11: Usa | H11: Usa | I11: Usa | J11: Usa | K11: Cada empresa tiene sus propios clientes y saldos.
A12: Comercial | B12: Compras | C12: Vía AEP | D12: Vía AEP | E12: Usa | F12: Vía AEP | G12: Vía AEP | H12: Vía AEP | I12: Vía AEP | J12: Vía AEP | K12: AEP compra todos los materiales y los vende a cada empresa. Las demás hacen requisiciones y sus propias órdenes de servicio.
A13: Comercial | B13: Almacén | C13: Usa | D13: Usa | E13: Usa | F13: Usa | G13: Opcional | H13: Usa | I13: No aplica | J13: Usa | K13: CSC, Ergo y Mario Contreras Farfán: almacén de obra. AEP: bodega central. Clavicon y Balken: materia prima y producto terminado. Loma Racing: refacciones si se controlan.
A14: Finanzas | B14: Tesorería | C14: Usa | D14: Usa | E14: Usa | F14: Usa | G14: Usa | H14: Usa | I14: Usa | J14: Usa | K14: Todas tienen cuentas bancarias propias.
A15: Finanzas | B15: Cuentas por pagar | C15: Usa | D15: Usa | E15: Usa | F15: Usa | G15: Usa | H15: Usa | I15: Usa | J15: Usa | K15: Todas tienen proveedores o saldos por pagar.
A16: Finanzas | B16: Presupuestos | C16: Usa | D16: Usa | E16: Usa | F16: Usa | G16: Usa | H16: Usa | I16: Usa | J16: Usa | K16: Presupuesto anual por empresa; por obra solo CSC, Ergo y Mario Contreras Farfán.
A17: Finanzas | B17: Contabilidad | C17: Usa | D17: Usa | E17: Usa | F17: Usa | G17: Usa | H17: Usa | I17: Usa | J17: Usa | K17: Cada razón social lleva su contabilidad.
... A27: Administración | B27: Configuración | C27: Compartido | D27: Compartido | E27: Compartido | F27: Compartido | G27: Compartido | H27: Compartido | I27: Compartido | J27: Compartido | K27: Usuarios y permisos se administran una vez para todo el grupo.
B29: Menús que usa | C29: =COUNTIF(C6:C27,"Usa")+COUNTIF(C6:C27,"Opcional") -> 17 | D29: =COUNTIF(D6:D27,"Usa")+COUNTIF(D6:D27,"Opcional") -> 16 | E29: =COUNTIF(E6:E27,"Usa")+COUNTIF(E6:E27,"Opcional") -> 17 | F29: =COUNTIF(F6:F27,"Usa")+COUNTIF(F6:F27,"Opcional") -> 15 | G29: =COUNTIF(G6:G27,"Usa")+COUNTIF(G6:G27,"Opcional") -> 15 | H29: =COUNTIF(H6:H27,"Usa")+COUNTIF(H6:H27,"Opcional") -> 15 | I29: =COUNTIF(I6:I27,"Usa")+COUNTIF(I6:I27,"Opcional") -> 13 | J29: =COUNTIF(J6:J27,"Usa")+COUNTIF(J6:J27,"Opcional") -> 16
B30: Vía AEP o compartido | C30: =COUNTIF(C6:C27,"Vía AEP")+COUNTIF(C6:C27,"Compartido") -> 3 | D30: =COUNTIF(D6:D27,"Vía AEP")+COUNTIF(D6:D27,"Compartido") -> 3 | E30: =COUNTIF(E6:E27,"Vía AEP")+COUNTIF(E6:E27,"Compartido") -> 2 | F30: =COUNTIF(F6:F27,"Vía AEP")+COUNTIF(F6:F27,"Compartido") -> 3 | G30: =COUNTIF(G6:G27,"Vía AEP")+COUNTIF(G6:G27,"Compartido") -> 3 | H30: =COUNTIF(H6:H27,"Vía AEP")+COUNTIF(H6:H27,"Compartido") -> 3 | I30: =COUNTIF(I6:I27,"Vía AEP")+COUNTIF(I6:I27,"Compartido") -> 3 | J30: =COUNTIF(J6:J27,"Vía AEP")+COUNTIF(J6:J27,"Compartido") -> 3
B31: Por confirmar | C31: =COUNTIF(C6:C27,"Por confirmar") -> 0 | D31: =COUNTIF(D6:D27,"Por confirmar") -> 0 | E31: =COUNTIF(E6:E27,"Por confirmar") -> 0 | F31: =COUNTIF(F6:F27,"Por confirmar") -> 0 | G31: =COUNTIF(G6:G27,"Por confirmar") -> 0 | H31: =COUNTIF(H6:H27,"Por confirmar") -> 0 | I31: =COUNTIF(I6:I27,"Por confirmar") -> 0 | J31: =COUNTIF(J6:J27,"Por confirmar") -> 0

Sheet Roles
A1: Roles del grupo
A2: Quién es cada rol, en qué empresa existe y qué menús usa. El detalle por menú está en la hoja Roles x menús.
A4: Rol | B4: Empresas donde existe | C4: Qué hace | D4: Menús con acceso total | E4: Menús de consulta | F4: Número de usuarios
A5: Dirección general | B5: Grupo | C5: Ve todo el grupo y autoriza órdenes y pagos grandes. | D5: Mi día, Tablero, Análisis, Gobierno | E5: Ventas, Cobranza, Compras, Almacén, Tesorería, Cuentas por pagar, Presupuestos, Contabilidad, Obras, Nómina, Mano de obra, Producción, Fletes, Mantenimiento BBVA, Recursos humanos, Legal y cumplimiento, Catálogos, Configuración
A6: Socio | B6: Grupo | C6: Consulta resultados y saldos. | D6: Mi día | E6: Tablero, Análisis, Gobierno
A7: Finanzas y tesorería | B7: Corporativo (todas) | C7: Paga, cobra, programa flujo y lleva presupuestos. | D7: Mi día, Análisis, Cobranza, Tesorería, Cuentas por pagar, Presupuestos | E7: Tablero, Ventas, Compras, Contabilidad, Nómina
A8: Contabilidad | B8: Corporativo (todas) | C8: Carga CFDI y estados de cuenta, concilia y cierra. | D8: Mi día, Contabilidad | E8: Ventas, Cobranza, Compras, Tesorería, Cuentas por pagar
A9: Recursos humanos | B9: Corporativo (todas) | C9: Empleados, asistencia, incidencias y nómina. | D9: Mi día, Nómina, Recursos humanos | E9: Gobierno, Tesorería
A10: Legal y cumplimiento | B10: Corporativo (todas) | C10: Contratos, juicios, crédito a clientes y controles. | D10: Mi día, Legal y cumplimiento | E10: Cobranza
A11: Marketing y relaciones públicas | B11: Corporativo (todas) | C11: Prospectos, redes y CRM. | D11: Mi día | E11: Ventas
A12: Compras | B12: AEP | C12: Compra materiales para todo el grupo y administra proveedores. | D12: Mi día, Compras, Catálogos | E12: Almacén, Cuentas por pagar
A13: Ventas y mostrador | B13: AEP, Clavicon, Balken, Loma Racing, Qx | C13: Cotiza, levanta OV y da seguimiento a clientes. | D13: Mi día, Ventas | E13: Cobranza, Almacén, Catálogos
A14: Almacenista | B14: AEP, Clavicon, Balken; CSC, Ergo y Mario Contreras Farfán (obra) | C14: Recibe, entrega, remisiona y cuenta inventario. | D14: Mi día, Almacén | E14: Compras
A15: Residente o supervisor de obra | B15: CSC, Ergodinova, Mario Contreras Farfán | C15: Requisiciones, avances, mano de obra y herramienta en obra. | D15: Mi día, Obras, Mano de obra | E15: Compras, Almacén, Presupuestos
A16: Arquitecto, diseñador o ingeniero civil | B16: CSC, Ergodinova, Mario Contreras Farfán | C16: Proyectos, planos y precios unitarios. | D16: Mi día, Obras | E16: Presupuestos
... A20: Chofer | B20: Loma Racing | C20: Ve sus viajes y registra combustible desde el celular. | D20: Mi día | E20: Fletes
A21: Coordinador BBVA | B21: CSC Loma | C21: Folios, cuadrillas y punto de equilibrio del contrato. | D21: Mi día, Mantenimiento BBVA
A22: TI | B22: Qx Soluciones | C22: Usuarios, permisos, catálogos y soporte. | D22: Mi día, Catálogos, Configuración
A24: Número de usuarios (amarillo): llénalo para dimensionar licencias y capacitación.

Sheet Roles x menús
A1: Acceso de cada rol por menú
A2: Total = puede capturar y modificar · Consulta = solo ver · vacío = no ve el menú. Cada rol ve solo los datos de sus empresas.
A4: Rol | B4: Mi día | C4: Tablero | D4: Análisis | E4: Gobierno | F4: Ventas | G4: Cobranza | H4: Compras | I4: Almacén | J4: Tesorería | K4: Cuentas por pagar | L4: Presupuestos | M4: Contabilidad | N4: Obras | O4: Nómina | P4: Mano de obra | Q4: Producción | R4: Fletes | S4: Mantenimiento BBVA | T4: Recursos humanos | U4: Legal y cumplimiento | V4: Catálogos | W4: Configuración
A5: Dirección general | B5: Total | C5: Total | D5: Total | E5: Total | F5: Consulta | G5: Consulta | H5: Consulta | I5: Consulta | J5: Consulta | K5: Consulta | L5: Consulta | M5: Consulta | N5: Consulta | O5: Consulta | P5: Consulta | Q5: Consulta | R5: Consulta | S5: Consulta | T5: Consulta | U5: Consulta | V5: Consulta | W5: Consulta
A6: Socio | B6: Total | C6: Consulta | D6: Consulta | E6: Consulta
A7: Finanzas y tesorería | B7: Total | C7: Total | D7: Total | F7: Total | G7: Total | H7: Consulta | J7: Total | K7: Total | L7: Total | M7: Consulta | O7: Consulta
A8: Contabilidad | B8: Total | F8: Consulta | G8: Consulta | H8: Consulta | J8: Consulta | K8: Consulta | M8: Total
A9: Recursos humanos | B9: Total | E9: Consulta | J9: Consulta | O9: Total | T9: Total
A10: Legal y cumplimiento | B10: Total | G10: Consulta | U10: Total
A11: Marketing y relaciones públicas | B11: Total | F11: Consulta
A12: Compras | B12: Total | H12: Total | I12: Consulta | K12: Consulta | V12: Total
A13: Ventas y mostrador | B13: Total | F13: Total | G13: Consulta | I13: Consulta | V13: Consulta
A14: Almacenista | B14: Total | H14: Consulta | I14: Total
A15: Residente o supervisor de obra | B15: Total | H15: Consulta | I15: Consulta | L15: Consulta | N15: Total | P15: Total
A16: Arquitecto, diseñador o ingeniero civil | B16: Total | L16: Consulta | N16: Total
A17: Jefe de producción | B17: Total | H17: Consulta | I17: Consulta | Q17: Total
A18: Operador de producción | B18: Total | Q18: Consulta
A19: Jefe de flota | B19: Total | I19: Consulta | R19: Total
A20: Chofer | B20: Total | R20: Consulta
A21: Coordinador BBVA | B21: Total | S21: Total
A22: TI | B22: Total | V22: Total | W22: Total
